<mujoco model="KIST 6-DoF Arm-Hand System">
	<compiler angle="radian" coordinate="local" inertiafromgeom="false" autolimits="true" meshdir="Meshes"/>

	<option>
		<flag gravity="enable" override="enable"/>
	</option>

	<option	timestep="0.001" gravity="0 0 -9.81" integrator="Euler" o_solref="0.005 0.2" o_solimp="0.95 0.98 0.01 0.5 2"
					cone="elliptic" jacobian="auto" solver="Newton" tolerance="1e-10" impratio="0.7"/>

	<visual>
		<global fovy="45" linewidth="2" glow="0.3"/>
		<quality shadowsize="1024" numslices="48"/>
		<scale forcewidth="0.05" contactwidth="0.15" contactheight="0.1" com="0.15" jointlength="0.5" jointwidth="0.05"
					 actuatorlength="0.5" actuatorwidth="0.3" framelength="1.5" framewidth="0.05"/>
		<rgba haze="0.6 0.8 0.9 1" force="1 0 0 0.5" com="0 0 1 1"/>
	</visual>
	
	<default>
		<geom contype="1" conaffinity="1" condim="3" margin="0.001" material="MatLink" rgba="0.4 0.5 0.5 1"/>
		<joint limited="false" damping="0.5" armature="0.1" stiffness="0" frictionloss="0.1"/>
	</default>

	<asset>
		<texture name="texplane" type="2d"     builtin="checker"  width="512" height="512" mark="edge"  
						 rgb1=".8 .8 .8" rgb2="0.5 0.5 0.5" markrgb="1 1 1" />
		<texture name="texgeom"  type="cube"   builtin="flat"     width="517" height="512" mark="cross" 
						 rgb1="0.8 0.6 0.4" rgb2="0.8 0.6 0.4" markrgb="1 1 1" />
		<texture name="sky"      type="skybox" builtin="gradient" width="512" height="512" 
						 rgb1="1 1 1" rgb2="0.6 0.8 1"/>

		<material name="MatGnd" reflectance="0" specular="1" shininess="0.1" rgba="0.5 0.5 0.5 1"/>
		<material name="MatLink" reflectance="0.5" specular="1" shininess="0.3" rgba="0.5 0.5 0.5 1"/>
		<material name="MatGeom" texture="texgeom" texuniform="true"/>
		<material name="MatPlane" texture="texplane" reflectance='0' texrepeat="1 1" texuniform="true"/>
	</asset>
	<!-- ######################################################################### -->

	<asset>
		<mesh name="base_link" file="base_link.STL" />
		<mesh name="body_link" file="body_link.STL" />
		<mesh name="RArmJ1_Link" file="RArmJ1_Link.STL" />
		<mesh name="RArmJ2_Link" file="RArmJ2_Link.STL" />
		<mesh name="RArmJ3_Link" file="RArmJ3_Link.STL" />
		<mesh name="RArmJ4_Link" file="RArmJ4_Link.STL" />
		<mesh name="RArmJ5_Link" file="RArmJ5_Link.STL" />
		<mesh name="RArmJ6_Link" file="RArmJ6_Link.STL" />
		<mesh name="Hand_RT1" file="Hand_RT1.STL" />
		<mesh name="Hand_RT2" file="Hand_RT2.STL" />
		<mesh name="Hand_RT3" file="Hand_RT3.STL" />
		<mesh name="Hand_RT4" file="Hand_RT4.STL" />
		<mesh name="Hand_RF1J1" file="Hand_RF1J1.STL" />
		<mesh name="Hand_RF1J2" file="Hand_RF1J2.STL" />
		<mesh name="Hand_RF1J3" file="Hand_RF1J3.STL" />
		<mesh name="Hand_RF1J4" file="Hand_RF1J4.STL" />
		<mesh name="Hand_RF2J1" file="Hand_RF2J1.STL" />
		<mesh name="Hand_RF2J2" file="Hand_RF2J2.STL" />
		<mesh name="Hand_RF2J3" file="Hand_RF2J3.STL" />
		<mesh name="Hand_RF2J4" file="Hand_RF2J4.STL" />
		<mesh name="Hand_RF3J1" file="Hand_RF3J1.STL" />
		<mesh name="Hand_RF3J2" file="Hand_RF3J2.STL" />
		<mesh name="Hand_RF3J3" file="Hand_RF3J3.STL" />
		<mesh name="Hand_RF3J4" file="Hand_RF3J4.STL" />
		<mesh name="LArmJ1_Link" file="LArmJ1_Link.STL" />
		<mesh name="LArmJ2_Link" file="LArmJ2_Link.STL" />
		<mesh name="LArmJ3_Link" file="LArmJ3_Link.STL" />
		<mesh name="LArmJ4_Link" file="LArmJ4_Link.STL" />
		<mesh name="LArmJ5_Link" file="LArmJ5_Link.STL" />
		<mesh name="LArmJ6_Link" file="LArmJ6_Link.STL" />
		<mesh name="Hand_LT1" file="Hand_LT1.STL" />
		<mesh name="Hand_LT2" file="Hand_LT2.STL" />
		<mesh name="Hand_LT3" file="Hand_LT3.STL" />
		<mesh name="Hand_LT4" file="Hand_LT4.STL" />
		<mesh name="Hand_LF1J1" file="Hand_LF1J1.STL" />
		<mesh name="Hand_LF1J2" file="Hand_LF1J2.STL" />
		<mesh name="Hand_LF1J3" file="Hand_LF1J3.STL" />
		<mesh name="Hand_LF1J4" file="Hand_LF1J4.STL" />
		<mesh name="Hand_LF2J1" file="Hand_LF2J1.STL" />
		<mesh name="Hand_LF2J2" file="Hand_LF2J2.STL" />
		<mesh name="Hand_LF2J3" file="Hand_LF2J3.STL" />
		<mesh name="Hand_LF2J4" file="Hand_LF2J4.STL" />
		<mesh name="Hand_LF3J1" file="Hand_LF3J1.STL" />
		<mesh name="Hand_LF3J2" file="Hand_LF3J2.STL" />
		<mesh name="Hand_LF3J3" file="Hand_LF3J3.STL" />
		<mesh name="Hand_LF3J4" file="Hand_LF3J4.STL" />
	</asset>

	<worldbody>
		<light diffuse="0.8 0.8 0.8" pos="0 0 10" castshadow="false"/>
		<geom name="Floor" type="plane" pos="0 0 0" size="0 0 10" material="MatPlane" solref="0.005 0.2" solimp="0.95 0.98 0.01 0.5 2"/>
		<geom name="BaseColumn" type="mesh" mesh="base_link" pos="0 0 0.705" rgba="0 0.7 0.1 1"/>

		<!-- Base body : Prismatic Joint -->
		<body name="body_link" pos="0 0 0.9">
			<joint name="J0" pos="0 0 0" axis="0 0 1" type="slide" limited="true" range="0 0.4"/>
			<inertial pos="-0.00831359 -5.0677e-05 -0.0209066" quat="0.704252 0.70994 -0.00330189 0.00177123"
								mass="3.81194" diaginertia="0.0165479 0.0118105 0.0108133"/>
			<geom type="mesh" rgba="0 0.6 1 1" mesh="body_link" contype="0" conaffinity="0"/>

			<!-- Right Arm & Hand -->
			<body name="RArmJ1_Link" pos="0 -0.21 0" quat="0.5 0.5 0.5 -0.5">
				<joint name="J1" pos="0 0 0" axis="0 0 1" limited="true" range="-1.57 1.57" damping="1"/>
				<inertial pos="0.000171163 -0.00645075 -0.0220591" quat="0.706537 -0.0286269 -0.0195098 0.706827"
									mass="1.00536" diaginertia="0.00104827 0.000666603 0.000662138"/>
				<geom type="mesh" mesh="RArmJ1_Link" rgba="0.4 0.4 0.3 1"/>

				<body name="RArmJ2_Link" pos="0 0.0001 0" quat="0.707107 -0.707107 0 0">
					<joint name="J2" pos="0 0 0" axis="0 0 -1" limited="true" range="-0.66 1.57" damping="1"/>
					<inertial pos="0.216305 -0.00804734 0.00250341" quat="0.463746 0.527593 0.53623 0.46802"
										mass="2.01441" diaginertia="0.00201835 0.00169624 0.00101412"/>
					<geom type="mesh" mesh="RArmJ2_Link" rgba="0.4 0.4 0.3 1"/>

					<body name="RArmJ3_Link" pos="0.29 0.0001 0" quat="0.5 0.5 0.5 -0.5">
						<joint name="J3" pos="0 0 0" axis="0 0 -1" limited="true" range="-2.42 0.72"/>
						<inertial pos="0.000151216 0.0891836 -0.00389852" quat="0.665518 -0.235081 0.240537 0.666307"
											mass="0.857155" diaginertia="0.00045032 0.000391672 0.000339662"/>
						<geom type="mesh" mesh="RArmJ3_Link" rgba="0.4 0.4 0.3 1"/>

						<body name="RArmJ4_Link" pos="0 0.29 0" quat="0 0 0.707107 0.707107">
							<joint name="J4" pos="0 0 0" axis="0 0 -1" limited="true" range="-1.57 4.71"/>
							<inertial pos="-6.1048e-05 -0.00689245 -0.073835" quat="0.707275 0.000334352 -0.000333138 0.706939" 
												mass="0.891802" diaginertia="0.000636377 0.000528082 0.000212557"/>
							<geom type="mesh" mesh="RArmJ4_Link" rgba="0.4 0.4 0.3 1"/>

							<body name="RArmJ5_Link" pos="0 0 0" quat="0.707107 0.707107 0 0">
								<joint name="J5" pos="0 0 0" axis="0 0 1" limited="true" range="-1.57 1.57"/>
								<inertial pos="-0.0109234 0.000314784 -0.000484401" quat="0.999999 -0.000308793 0.000172679 -0.00157371" 
													mass="0.588563" diaginertia="0.00017425 0.000126335 0.000111636"/>
								<geom type="mesh" mesh="RArmJ5_Link" rgba="0.4 0.4 0.3 1"/>

								<body name="RArmJ6_Link" pos="0 0 0" quat="0.5 0.5 0.5 0.5">
									<joint name="J6" pos="0 0 0" axis="0 0 -1" limited="true" range="-1.57 1.57"/>
									<inertial pos="0.0894019 0.000764982 0.00970289" quat="0.129674 0.669786 -0.155093 0.714505" 
														mass="0.317233" diaginertia="0.000124903 0.000112453 0.000100303"/>
									<geom type="mesh" mesh="RArmJ6_Link" rgba="0.4 0.4 0.3 1"/>
									<site name="rArm_EE" pos="0.080748 0 0" size="0.01" type="sphere" rgba="0 0 1 1"/>

									<!-- Right Hand : Thumb -->
									<body name="Hand_RT1" pos="0.125469 -0.010945 -0.006325" quat="0.706434 0.0308436 0.706434 -0.0308436">
										<joint name="RT1" pos="0 0 0" axis="0 0 -1" limited="true" range="0 1.8"/>
										<inertial pos="-5.49453e-05 -0.0141589 -0.0074296" quat="0.998952 -0.045631 0.000506768 -0.00355944"
															mass="0.0206488" diaginertia="1.87142e-06 1.36365e-06 9.66694e-07"/>
										<geom type="mesh" mesh="Hand_RT1" rgba="0.8 0.8 0.9 1"/>

										<body name="Hand_RT2" pos="-5e-05 -0.0441 0" quat="0.707107 -0.707107 0 0">
											<joint name="RT2" pos="0 0 0" axis="0 0 -1" limited="true" range="-1.57 1.57"/>
											<inertial pos="-2.98452e-12 0.000573264 0.00797915" quat="0.702887 0.711302 0 0"
																mass="0.00152599" diaginertia="6.01888e-08 5.38721e-08 3.40722e-08"/>
											<geom type="mesh" mesh="Hand_RT2" rgba="0.8 0.8 0.9 1"/>

											<body name="Hand_RT3" pos="0 0 0" quat="0.5 -0.5 0.5 0.5">
												<joint name="RT3" pos="0 0 0" axis="0 0 1" limited="true" range="0 1.8"/>
												<inertial pos="0.02005 0.000469812 -0.0005" quat="0.473244 0.525395 0.525395 0.473244"
																	mass="0.0341379" diaginertia="3.07195e-06 2.04238e-06 1.54556e-06"/>
												<geom type="mesh" mesh="Hand_RT3" rgba="0.752941 0.752941 0.752941 1"/>

												<body name="Hand_RT4" pos="0.0401 0 -0.000675">
													<joint name="RT4" pos="0 0 0" axis="0 0 -1" limited="true" range="-1.8 0"/>
													<inertial pos="0.0191982 6.45169e-05 -0.000413501" quat="0.778805 -0.000659988 -0.000727599 0.627266"
																		mass="0.0098292" diaginertia="6.11343e-07 4.92403e-07 3.88556e-07"/>
													<geom name="rHand_tip1" type="mesh" mesh="Hand_RT4" rgba="0.752941 0.752941 0.752941 1"/>
													<site name="RT_EE" pos="0.020748 0 0" size="0.002" type="sphere" rgba="0 0 1 1"/>
												</body>
											</body>
										</body>
									</body>

									<!-- Right Hand : Index finger -->
									<body name="Hand_RF1J1" pos="0.1959 -0.033168 0.006325" quat="0.706434 0.0308436 0.706434 -0.0308436">
										<joint name="RF1J1" pos="0 0 0" axis="0 0 -1" limited="true" range="-1.57 1.57"/>
										<inertial pos="-2.49922e-12 -0.000573264 -0.00797915" quat="0.702887 0.711302 0 0" 
															mass="0.00152599" diaginertia="6.01888e-08 5.38721e-08 3.40722e-08"/>
										<geom type="mesh" mesh="Hand_RF1J1" rgba="0.792 0.820 0.933 1"/>

										<body name="Hand_RF1J2" pos="0 0.0005 0" quat="0.5 0.5 -0.5 0.5">
											<joint name="RF1J2" pos="0 0 0" axis="0 0 1" limited="true" range="0 1.8"/>
											<inertial pos="0.02005 0.000469812 0" quat="0.473244 0.525395 0.525395 0.473244"
																mass="0.0341379" diaginertia="3.07195e-06 2.04238e-06 1.54556e-06"/>
											<geom type="mesh" mesh="Hand_RF1J2" rgba="0.792 0.820 0.933 1"/>

											<body name="Hand_RF1J3" pos="0.0401 0 -0.000125">
												<joint name="RF1J3" pos="0 0 0" axis="0 0 -1" limited="true" range="-1.8 0"/>
												<inertial pos="0.0213453 0.000452463 -0.000262751" quat="0.47733 0.521686 0.521686 0.47733"
																	mass="0.0177234" diaginertia="1.57868e-06 1.06889e-06 7.79807e-07"/>
												<geom type="mesh" mesh="Hand_RF1J3" rgba="0.792 0.820 0.933 1"/>

												<body name="Hand_RF1J4" pos="0.03005 0 -5e-05">
													<joint name="RF1J4" pos="0 0 0" axis="0 0 -1" limited="true" range="-1.8 0"/>
													<inertial pos="0.0191982 6.45169e-05 -0.000413501" quat="0.778805 -0.000659988 -0.000727599 0.627266" 
																		mass="0.0098292" diaginertia="6.11343e-07 4.92403e-07 3.88556e-07"/>
													<geom name="rHand_tip2" type="mesh" mesh="Hand_RF1J4" rgba="0.792 0.820 0.933 1"/>
													<site name="RF1_EE" pos="0.020748 0 0"  size="0.002" type="sphere" rgba="0 0 1 1"/>
												</body>
											</body>
										</body>
									</body>

									<!-- Right Hand : Middle finger -->
									<body name="Hand_RF2J1" pos="0.197348 0 0.006325" quat="0.707107 0 0.707107 0">
										<joint name="RF2J1" pos="0 0 0" axis="0 0 -1" limited="true" range="-1.57 1.57"/>
										<inertial pos="-2.49577e-12 -0.000573266 -0.00797915" quat="0.702887 0.711302 0 0"
															mass="0.00152599" diaginertia="6.01889e-08 5.38721e-08 3.40722e-08"/>
										<geom type="mesh" mesh="Hand_RF2J1" rgba="0.792 0.820 0.933 1"/>

										<body name="Hand_RF2J2" pos="0 0.0005 0" quat="0.5 0.5 -0.5 0.5">
											<joint name="RF2J2" pos="0 0 0" axis="0 0 1" limited="true" range="0 1.8"/>
											<inertial pos="0.02005 0.000469812 0" quat="0.473244 0.525395 0.525395 0.473244"
																mass="0.0341379" diaginertia="3.07195e-06 2.04238e-06 1.54556e-06"/>
											<geom type="mesh" mesh="Hand_RF2J2" rgba="0.792 0.820 0.933 1"/>
											
											<body name="Hand_RF2J3" pos="0.0401 0 -0.000125">
												<joint name="RF2J3" pos="0 0 0" axis="0 0 -1" limited="true" range="-1.8 0"/>
												<inertial pos="0.0213453 0.000452463 -0.000262751" quat="0.47733 0.521686 0.521686 0.47733" 
																	mass="0.0177234" diaginertia="1.57868e-06 1.06889e-06 7.79807e-07"/>
												<geom type="mesh" mesh="Hand_RF2J3" rgba="0.792 0.820 0.933 1"/>

												<body name="Hand_RF2J4" pos="0.03005 0 -5e-05">
													<joint name="RF2J4" pos="0 0 0" axis="0 0 -1" limited="true" range="-1.8 0"/>
													<inertial pos="0.0191982 6.45145e-05 -0.000413505" quat="0.778809 -0.000661237 -0.000728567 0.62726"
																		mass="0.0098292" diaginertia="6.11342e-07 4.92404e-07 3.88555e-07"/>
													<geom name="rHand_tip3" type="mesh" mesh="Hand_RF2J4" rgba="0.792 0.820 0.933 1"/>
													<site name="RF2_EE" pos="0.020748 0 0" size="0.002" type="sphere" rgba="0 0 1 1"/>
												</body>
											</body>
										</body>
									</body>

									<!-- Right Hand : Ring finger -->
									<body name="Hand_RF3J1" pos="0.1959 0.033168 0.006325" quat="0.0308436 0.706434 0.0308436 -0.706434">
										<joint name="RF3J1" pos="0 0 0" axis="0 0 1" limited="true" range="-1.57 1.57"/>
										<inertial pos="0 0.000573267 0.00797915" quat="0.702887 0.711302 0 0"
															mass="0.00152599" diaginertia="6.01888e-08 5.38721e-08 3.40722e-08"/>
										<geom type="mesh" mesh="Hand_RF3J1" rgba="0.752941 0.752941 0.752941 1"/>

										<body name="Hand_RF3J2" pos="0 -0.0005 0" quat="0.5 0.5 0.5 -0.5">
											<joint name="RF3J2" pos="0 0 0" axis="0 0 -1" limited="true" range="0 1.8"/>
											<inertial pos="0.02005 -0.000469812 0" quat="0.525395 0.473244 0.473244 0.525395"
																mass="0.0341379" diaginertia="3.07195e-06 2.04238e-06 1.54556e-06"/>
											<geom type="mesh" mesh="Hand_RF3J2" rgba="0.752941 0.752941 0.752941 1"/>

											<body name="Hand_RF3J3" pos="0.0401 0 0.000125">
												<joint name="RF3J3" pos="0 0 0" axis="0 0 1" limited="true" range="-1.8 0"/>
												<inertial pos="0.0213453 -0.000452463 0.000262751" quat="0.521686 0.47733 0.47733 0.521686"
																	mass="0.0177234" diaginertia="1.57868e-06 1.06889e-06 7.79807e-07"/>
												<geom type="mesh" mesh="Hand_RF3J3" rgba="0.752941 0.752941 0.752941 1"/>

												<body name="Hand_RF3 J4" pos="0.03005 0 5e-05">
													<joint name="RF3J4" pos="0 0 0" axis="0 0 1" limited="true" range="-1.8 0"/>
													<inertial pos="0.0191982 -6.4521e-05 0.000413504" quat="0.627261 0.000727904 0.000661492 0.778808"
																		mass="0.00982919" diaginertia="6.11342e-07 4.92404e-07 3.88555e-07"/>
													<geom name="rHand_tip4" type="mesh" mesh="Hand_RF3J4" rgba="0 0.6 1 1"/>
													<site name="RF3_EE" pos="0.020748 0 0" size="0.002" type="sphere" rgba="0 0 1 1"/>
												</body>
											</body>
										</body>
									</body>
								</body>
							</body>
						</body>
					</body>
				</body>
			</body>

			<!-- Left Arm & Hand -->
			<!--<body name="LArmJ1_Link" pos="0 0.21 0" quat="0.707107 0.707107 0 0">
					<inertial pos="-0.00645076 -0.000171167 0.0220591" quat="0.99947 0.0318946 -0.00643887 0.000191769" mass="1.00536" diaginertia="0.00104827 0.000666601 0.000662141" />
					<joint name="J7" pos="0 0 0" axis="0 0 -1" limited="true" range="-3.14 3.14" damping="0.05" frictionloss="0.1" />
					<geom type="mesh" rgba="0.752941 0.752941 0.752941 1" mesh="LArmJ1_Link" />
					<body name="LArmJ2_Link" pos="0.0001 0 0" quat="0.5 0.5 -0.5 -0.5">
							<inertial pos="0.216305 -0.00804734 -0.00250316" quat="0.5276 0.463739 0.468027 0.536223" mass="2.01441" diaginertia="0.00201835 0.00169624 0.00101412" />
							<joint name="J8" pos="0 0 0" axis="0 0 -1" limited="true" range="-3.14 3.14" damping="0.05" frictionloss="0.1" />
							<geom type="mesh" rgba="0.752941 0.752941 0.752941 1" mesh="LArmJ2_Link" />
							<body name="LArmJ3_Link" pos="0.29 0 0" quat="0.5 0.5 0.5 -0.5">
									<inertial pos="-0.000128598 0.0891836 -0.00387696" quat="0.665807 -0.239802 0.236086 0.665928" mass="0.857155" diaginertia="0.000450482 0.000391642 0.000339529" />
									<joint name="J9" pos="0 0 0" axis="0 0 -1" limited="true" range="-2.42 0.72" damping="0.05" frictionloss="0.1" />
									<geom type="mesh" rgba="0.752941 0.752941 0.752941 1" mesh="LArmJ3_Link" />
									<body name="LArmJ4_Link" pos="0 0.29 0" quat="0.707107 0.707107 0 0">
											<inertial pos="-3.77128e-05 -0.00690517 0.0738294" quat="0.706939 -0.000333138 0.000334352 0.707275" mass="0.891802" diaginertia="0.000636377 0.000528082 0.000212557" />
											<joint name="J10" pos="0 0 0" axis="0 0 1" limited="true" range="-1.57 1.57" damping="0.05" frictionloss="0.1" />
											<geom type="mesh" rgba="0.752941 0.752941 0.752941 1" mesh="LArmJ4_Link" />
											<body name="LArmJ5_Link" pos="0 0 0" quat="0.707107 0.707107 0 0">
													<inertial pos="-0.0109235 -0.00031722 -0.000482639" quat="0.999999 0.000262214 2.44885e-05 0.00141025" mass="0.588563" diaginertia="0.00017425 0.000126364 0.000111607" />
													<joint name="J11" pos="0 0 0" axis="0 0 1" limited="true" range="-1.57 1.57" damping="0.05" frictionloss="0.1" />
													<geom type="mesh" rgba="0.752941 0.752941 0.752941 1" mesh="LArmJ5_Link" />
													<body name="LArmJ6_Link" pos="0 0 0" quat="0.5 0.5 -0.5 -0.5">
															<inertial pos="0.0998753 0.00248508 -0.007873" quat="0.175833 0.694607 -0.165886 0.677558" mass="0.412582" diaginertia="0.000204009 0.000163744 0.000133917" />
															<joint name="J12" pos="0 0 0" axis="0 0 1" limited="true" range="-1.57 1.57" damping="0.05" frictionloss="0.1" />
															<geom type="mesh" rgba="0.752941 0.752941 0.752941 1" mesh="LArmJ6_Link" />
															<body name="Hand_LT1" pos="0.125469 -0.010945 0.006325" quat="0.706434 0.0308436 0.706434 -0.0308436">
																	<inertial pos="5.95167e-05 -0.010198 -0.00729248" quat="0.999154 -0.0400283 -0.000943336 0.00942323" mass="0.0301516" diaginertia="2.62399e-06 2.08439e-06 1.37873e-06" />
																	<joint name="LT1" pos="0 0 0" axis="0 0 -1" limited="true" range="-3.14 3.14" damping="0.05" frictionloss="0.1" />
																	<geom type="mesh" rgba="0.752941 0.752941 0.752941 1" mesh="Hand_LT1" />
																	<body name="Hand_LT2" pos="5e-05 -0.0441 0" quat="0.707107 -0.707107 0 0">
																			<inertial pos="0 -0.000573267 0.00797915" quat="0.711302 0.702887 0 0" mass="0.00152599" diaginertia="6.01888e-08 5.38721e-08 3.40722e-08" />
																			<joint name="LT2" pos="0 0 0" axis="0 0 -1" limited="true" range="-3.14 3.14" damping="0.05" frictionloss="0.1" />
																			<geom type="mesh" rgba="0.752941 0.752941 0.752941 1" mesh="Hand_LT2" />
																			<body name="Hand_LT3" pos="0 0 0" quat="1.9457e-12 -1.9457e-12 0.707107 -0.707107">
																					<inertial pos="-0.000469812 0.02005 -0.0005" quat="0.743021 0.669268 0 0" mass="0.0341379" diaginertia="3.07195e-06 2.04238e-06 1.54556e-06" />
																					<joint name="LT3" pos="0 0 0" axis="0 0 1" limited="true" range="-3.14 3.14" damping="0.05" frictionloss="0.1" />
																					<geom type="mesh" rgba="0.752941 0.752941 0.752941 1" mesh="Hand_LT3" />
																					<body name="Hand_LT4" pos="0 0.0401 -0.000675" quat="0.707107 0 0 -0.707107">
																							<inertial pos="-0.0191982 -6.4521e-05 -0.000413504" quat="0.778808 0.000661492 0.000727904 0.627261" mass="0.00982919" diaginertia="6.11342e-07 4.92404e-07 3.88555e-07" />
																							<joint name="LT4" pos="0 0 0" axis="0 0 -1" limited="true" range="-3.14 3.14" damping="0.05" frictionloss="0.1" />
																							<geom type="mesh" rgba="0.752941 0.752941 0.752941 1" mesh="Hand_LT4" />
																					</body>
																			</body>
																	</body>
															</body>
															<body name="Hand_LF1J1" pos="0.1959 -0.033168 -0.006325" quat="0.706434 0.0308436 0.706434 -0.0308436">
																	<inertial pos="0 0.000573267 -0.00797915" quat="0.711302 0.702887 0 0" mass="0.00152599" diaginertia="6.01888e-08 5.38721e-08 3.40722e-08" />
																	<joint name="LF1J1" pos="0 0 0" axis="0 0 -1" limited="true" range="-3.14 3.14" damping="0.05" frictionloss="0.1" />
																	<geom type="mesh" rgba="0.752941 0.752941 0.752941 1" mesh="Hand_LF1J1" />
																	<body name="Hand_LF1J2" pos="0 0 0" quat="0 0 -0.707107 -0.707107">
																			<inertial pos="-0.000469812 0.02005 -0.0005" quat="0.743021 0.669268 0 0" mass="0.0341379" diaginertia="3.07195e-06 2.04238e-06 1.54556e-06" />
																			<joint name="LF1J2" pos="0 0 0" axis="0 0 1" limited="true" range="-3.14 3.14" damping="0.05" frictionloss="0.1" />
																			<geom type="mesh" rgba="0.752941 0.752941 0.752941 1" mesh="Hand_LF1J2" />
																			<body name="Hand_LF1J3" pos="0 0.0401 -0.000625" quat="0.707107 0 0 0.707107">
																					<inertial pos="0.0213453 0.000452463 -0.000262751" quat="0.47733 0.521686 0.521686 0.47733" mass="0.0177234" diaginertia="1.57868e-06 1.06889e-06 7.79807e-07" />
																					<joint name="LF1J3" pos="0 0 0" axis="0 0 -1" limited="true" range="-3.14 3.14" damping="0.05" frictionloss="0.1" />
																					<geom type="mesh" rgba="0.752941 0.752941 0.752941 1" mesh="Hand_LF1J3" />
																					<body name="Hand_LF1J4" pos="0.03005 0 -5e-05">
																							<inertial pos="0.0191982 6.4521e-05 -0.000413504" quat="0.778808 -0.000661492 -0.000727904 0.627261" mass="0.00982919" diaginertia="6.11342e-07 4.92404e-07 3.88555e-07" />
																							<joint name="LF1J4" pos="0 0 0" axis="0 0 -1" limited="true" range="-3.14 3.14" damping="0.05" frictionloss="0.1" />
																							<geom type="mesh" rgba="0.752941 0.752941 0.752941 1" mesh="Hand_LF1J4" />
																					</body>
																			</body>
																	</body>
															</body>
															<body name="Hand_LF2J1" pos="0.197348 0 -0.006325" quat="0 0.707107 0 -0.707107">
																	<inertial pos="2.49563e-12 -0.000573266 0.00797915" quat="0.711302 0.702887 0 0" mass="0.00152599" diaginertia="6.01889e-08 5.38721e-08 3.40722e-08" />
																	<joint name="LF2J1" pos="0 0 0" axis="0 0 1" limited="true" range="-3.14 3.14" damping="0.05" frictionloss="0.1" />
																	<geom type="mesh" rgba="0.752941 0.752941 0.752941 1" mesh="Hand_LF2J1" />
																	<body name="Hand_LF2J2" pos="0 0 0" quat="0.5 0.5 0.5 -0.5">
																			<inertial pos="0.02005 0.000469812 -0.0005" quat="0.473244 0.525395 0.525395 0.473244" mass="0.0341379" diaginertia="3.07195e-06 2.04238e-06 1.54556e-06" />
																			<joint name="LF2J2" pos="0 0 0" axis="0 0 1" limited="true" range="-3.14 3.14" damping="0.05" frictionloss="0.1" />
																			<geom type="mesh" rgba="0.752941 0.752941 0.752941 1" mesh="Hand_LF2J2" />
																			<body name="Hand_LF2J3" pos="0.0401 0 -0.000625">
																					<inertial pos="0.0213453 0.000452463 -0.000262751" quat="0.47733 0.521686 0.521686 0.47733" mass="0.0177234" diaginertia="1.57868e-06 1.06889e-06 7.79807e-07" />
																					<joint name="LF2J3" pos="0 0 0" axis="0 0 -1" limited="true" range="-3.14 3.14" damping="0.05" frictionloss="0.1" />
																					<geom type="mesh" rgba="0.752941 0.752941 0.752941 1" mesh="Hand_LF2J3" />
																					<body name="Hand_LF2J4" pos="0.03005 0 -5e-05">
																							<inertial pos="0.0191982 6.45145e-05 -0.000413505" quat="0.778809 -0.000661237 -0.000728567 0.62726" mass="0.0098292" diaginertia="6.11342e-07 4.92404e-07 3.88555e-07" />
																							<joint name="LF2J4" pos="0 0 0" axis="0 0 -1" limited="true" range="-3.14 3.14" damping="0.05" frictionloss="0.1" />
																							<geom type="mesh" rgba="0.752941 0.752941 0.752941 1" mesh="Hand_LF2J4" />
																					</body>
																			</body>
																	</body>
															</body>
															<body name="Hand_LF3J1" pos="0.1959 0.033168 -0.006325" quat="0.0308436 0.706434 0.0308436 -0.706434">
																	<inertial pos="2.49889e-12 -0.000573264 0.00797915" quat="0.711302 0.702887 0 0" mass="0.00152599" diaginertia="6.01888e-08 5.38721e-08 3.40722e-08" />
																	<joint name="LF3J1" pos="0 0 0" axis="0 0 1" limited="true" range="-3.14 3.14" damping="0.05" frictionloss="0.1" />
																	<geom type="mesh" rgba="0.752941 0.752941 0.752941 1" mesh="Hand_LF3J1" />
																	<body name="Hand_LF3J2" pos="0 0.0005 0" quat="0.5 0.5 0.5 -0.5">
																			<inertial pos="0.02005 0.000469812 0" quat="0.473244 0.525395 0.525395 0.473244" mass="0.0341379" diaginertia="3.07195e-06 2.04238e-06 1.54556e-06" />
																			<joint name="LF3J2" pos="0 0 0" axis="0 0 1" limited="true" range="-3.14 3.14" damping="0.05" frictionloss="0.1" />
																			<geom type="mesh" rgba="0.752941 0.752941 0.752941 1" mesh="Hand_LF3J2" />
																			<body name="Hand_LF3J3" pos="0.0401 0 -0.000125">
																					<inertial pos="0.0213453 0.000452463 -0.000262751" quat="0.47733 0.521686 0.521686 0.47733" mass="0.0177234" diaginertia="1.57868e-06 1.06889e-06 7.79807e-07" />
																					<joint name="LF3J3" pos="0 0 0" axis="0 0 -1" limited="true" range="-3.14 3.14" damping="0.05" frictionloss="0.1" />
																					<geom type="mesh" rgba="0.752941 0.752941 0.752941 1" mesh="Hand_LF3J3" />
																					<body name="Hand_LF3J4" pos="0.0596822 0 0.339997" quat="0 0.996195 0 -0.0871557">
																							<inertial pos="0.0488449 -6.45169e-05 0.3371" quat="0.624821 0.0686032 0.0553264 0.775778" mass="0.0098292" diaginertia="6.11343e-07 4.92403e-07 3.88556e-07" />
																							<joint name="LF3J4" pos="0 0 0" axis="0 0 1" limited="true" range="-3.14 3.14" damping="0.05" frictionloss="0.1" />
																							<geom type="mesh" rgba="0.752941 0.752941 0.752941 1" mesh="Hand_LF3J4" />
																					</body>
																			</body>
																	</body>
															</body>
													</body>
											</body>
									</body>
							</body>
					</body>
			</body>-->
		</body>

		<!--<body name="rid1" pos="0.35 -0.25 0.2" euler="0 0 0">
			<inertial pos="0 0 0" mass="1" diaginertia="6.01888e-05 5.38721e-05 3.40722e-05" />
			<geom name="rid_1" size="0.01 0.2" pos="0 0 0" euler="0 0 0" type="cylinder" rgba="1.5 0 0 1" />
		</body>

		<body name="large_grasp" pos="0.35 -0.25 0.45" euler="0 0 0">
			<joint type="free" />
			<inertial pos="0 0 0" euler="0 0 0" mass="0.1" diaginertia="6.01888e-08 5.38721e-08 3.40722e-08" />
			<geom name="object_1" size="0.05 0.06" pos="0 0 0" euler="1.57 0 0" type="capsule" rgba="0 1.5 0 1" />
		</body>-->

	</worldbody>

	<contact>
		<!--<exclude body1="base_link" body2="body_link" />
		<exclude body1="base_link" body2="RArmJ2_Link" />
		<exclude body1="base_link" body2="RArmJ3_Link" />
		<exclude body1="body_link" body2="RArmJ1_Link" />-->
		<exclude body1="RArmJ4_Link" body2="RArmJ6_Link" />
		<exclude body1="RArmJ6_Link" body2="Hand_RT1" />
		<exclude body1="RArmJ6_Link" body2="Hand_RT2" />
		<exclude body1="RArmJ6_Link" body2="Hand_RT3" />
	</contact>

	<!--<contact>
		<pair geom1="object_1" geom2="plate1" />
		<pair geom1="object_1" geom2="rHand_tip1" />
		<pair geom1="object_1" geom2="rHand_tip2" />
		<pair geom1="object_1" geom2="rHand_tip3" />
		<pair geom1="object_1" geom2="rHand_tip4" />
	</contact>-->

	<actuator>
		<general name="J_0" joint="J0" gear="1" ctrllimited="false" ctrlrange="-250 250" />
		<general name="J_1" joint="J1" gear="1" ctrllimited="false" ctrlrange="-250 250" />
		<general name="J_2" joint="J2" gear="1" ctrllimited="false" ctrlrange="-250 250" />
		<general name="J_3" joint="J3" gear="1" ctrllimited="false" ctrlrange="-250 250" />
		<general name="J_4" joint="J4" gear="1" ctrllimited="false" ctrlrange="-250 250" />
		<general name="J_5" joint="J5" gear="1" ctrllimited="false" ctrlrange="-250 250" />
		<general name="J_6" joint="J6" gear="1" ctrllimited="false" ctrlrange="-250 250" />
		<general name="RT_1" joint="RT1" gear="1" ctrllimited="false" ctrlrange="-100 100" />
		<general name="RT_2" joint="RT2" gear="1" ctrllimited="false" ctrlrange="-100 100" />
		<general name="RT_3" joint="RT3" gear="1" ctrllimited="false" ctrlrange="-100 100" />
		<general name="RT_4" joint="RT4" gear="1" ctrllimited="false" ctrlrange="-100 100" />
		<general name="RF1J_1" joint="RF1J1" gear="1" ctrllimited="false" ctrlrange="-100 100" />
		<general name="RF1J_2" joint="RF1J2" gear="1" ctrllimited="false" ctrlrange="-100 100" />
		<general name="RF1J_3" joint="RF1J3" gear="1" ctrllimited="false" ctrlrange="-100 100" />
		<general name="RF1J_4" joint="RF1J4" gear="1" ctrllimited="false" ctrlrange="-100 100" />
		<general name="RF2J_1" joint="RF2J1" gear="1" ctrllimited="false" ctrlrange="-100 100" />
		<general name="RF2J_2" joint="RF2J2" gear="1" ctrllimited="false" ctrlrange="-100 100" />
		<general name="RF2J_3" joint="RF2J3" gear="1" ctrllimited="false" ctrlrange="-100 100" />
		<general name="RF2J_4" joint="RF2J4" gear="1" ctrllimited="false" ctrlrange="-100 100" />
		<general name="RF3J_1" joint="RF3J1" gear="1" ctrllimited="false" ctrlrange="-100 100" />
		<general name="RF3J_2" joint="RF3J2" gear="1" ctrllimited="false" ctrlrange="-100 100" />
		<general name="RF3J_3" joint="RF3J3" gear="1" ctrllimited="false" ctrlrange="-100 100" />
		<general name="RF3J_4" joint="RF3J4" gear="1" ctrllimited="false" ctrlrange="-100 100" />
	</actuator>

</mujoco>
