<?xml version="1.0" encoding="utf-8"?>

<robot
  name="yori">

  <link name="world"/>

  <joint name="dummy_joint" type="fixed">
    <origin rpy="0 0 0" xyz="0.0 0.0 0.0"/>
    <parent link="world"/>
    <child link="stand"/>
  </joint>

  <link name="stand">
    <inertial>
      <origin
        xyz="-0.0085778 0.0095158 0.23739"
        rpy="0 0 0" />
      <mass
        value="21.179" />
      <inertia
        ixx="0.81876"
        ixy="5.7027E-05"
        ixz="0.011142"
        iyy="0.55802"
        iyz="-0.0011748"
        izz="0.94951" />
    </inertial>
    <visual>
      <origin
        xyz="0 0 0"
        rpy="0 0 0" />
      <geometry>
        <mesh
          filename="package://yori_description/meshes/yori/base_link_bottom_origin.dae"/>
      </geometry>
      <material
        name="">
        <color
          rgba="0.75294 0.75294 0.75294 1" />
      </material>
    </visual>
    <collision>
      <origin
        xyz="0 0 0"
        rpy="0 0 0" />
      <geometry>
        <mesh
          filename="package://yori_description/meshes/yori/base_link_bottom_origin.dae" />
      </geometry>
    </collision>
  </link>

  <link
    name="clavicle">
    <inertial>
      <origin
        xyz="9.8188E-09 9.903E-08 0.098709"
        rpy="0 0 0" />
      <mass
        value="1.4566" />
      <inertia
        ixx="0.0055396"
        ixy="-3.4638E-09"
        ixz="2.6541E-09"
        iyy="0.0025131"
        iyz="-2.5864E-09"
        izz="0.003913" />
    </inertial>
    <visual>
      <origin
        xyz="0 0 0"
        rpy="0 0 0" />
      <geometry>
        <mesh
          filename="package://yori_description/meshes/yori/clavicle.dae" />
      </geometry>
      <material
        name="">
        <color
          rgba="0.75294 0.75294 0.75294 1" />
      </material>
    </visual>
    <collision>
      <origin
        xyz="0 0 0"
        rpy="0 0 0" />
      <geometry>
        <mesh
          filename="package://yori_description/meshes/yori/clavicle.dae" />
      </geometry>
    </collision>
  </link>

  <joint
    name="clavicle"
    type="revolute">
    <origin
      xyz="0 0 1.1276"
      rpy="0 0 0" />
    <parent
      link="stand" />
    <child
      link="clavicle" />
    <axis
      xyz="0 0 1" />
    <limit
      lower="-3.14159"
      upper="3.14159"
      effort="30"
      velocity="10" />
    <dynamics
      damping="21.75"
      friction="3.48" />
  </joint>
  
  <link
    name="shoulder_left">
    <inertial>
      <origin
        xyz="-1.5918E-06 0.049429 0.00095652"
        rpy="0 0 0" />
      <mass
        value="1.1411" />
      <inertia
        ixx="0.0015526"
        ixy="-1.1483E-08"
        ixz="8.2634E-09"
        iyy="0.0024227"
        iyz="-7.1818E-05"
        izz="0.0029867" />
    </inertial>
    <visual>
      <origin
        xyz="0 0 0"
        rpy="0 0 0" />
      <geometry>
        <mesh
          filename="package://yori_description/meshes/yori/shoulder_left.dae" />
      </geometry>
      <material
        name="">
        <color
          rgba="0.75294 0.75294 0.75294 1" />
      </material>
    </visual>
    <collision>
      <origin
        xyz="0 0 0"
        rpy="0 0 0" />
      <geometry>
        <mesh
          filename="package://yori_description/meshes/yori/shoulder_left.dae" />
      </geometry>
    </collision>
  </link>

  <joint
    name="shoulder_left_joint"
    type="revolute">
    <origin
      xyz="0 0.21 0.117"
      rpy="0 0 0" />
    <parent
      link="clavicle" />
    <child
      link="shoulder_left" />
    <axis
      xyz="0 0 1" />
    <limit
      lower="-2.2689"
      upper="2.2689"
      effort="30"
      velocity="10" />
    <dynamics
      damping="21.75"
      friction="3.48" />
  </joint>

  <link
    name="upperarm_left">
    <inertial>
      <origin
        xyz="-0.0060639 0.08402 -0.0010615"
        rpy="0 0 0" />
      <mass
        value="0.77878" />
      <inertia
        ixx="0.0013093"
        ixy="2.2239E-05"
        ixz="-2.5264E-06"
        iyy="0.00072415"
        iyz="1.4488E-05"
        izz="0.0018707" />
    </inertial>
    <visual>
      <origin
        xyz="0 0 0"
        rpy="0 0 0" />
      <geometry>
        <mesh
          filename="package://yori_description/meshes/yori/upperarm_left.dae" />
      </geometry>
      <material
        name="">
        <color
          rgba="0.75294 0.75294 0.75294 1" />
      </material>
    </visual>
    <collision>
      <origin
        xyz="0 0 0"
        rpy="0 0 0" />
      <geometry>
        <mesh
          filename="package://yori_description/meshes/yori/upperarm_left.dae" />
      </geometry>
    </collision>
  </link>

  <joint
    name="upperarm_left_joint"
    type="revolute">
    <origin
      xyz="0 0.15 0"
      rpy="-1.5708 0 0" />
    <parent
      link="shoulder_left" />
    <child
      link="upperarm_left" />
    <axis
      xyz="0 0 1" />
    <limit
      lower="-3.14159"
      upper="3.14159"
      effort="30"
      velocity="10" />
    <dynamics
      damping="21.75"
      friction="3.48" />
  </joint>

  <link
    name="forearm_left">
    <inertial>
      <origin
        xyz="0.19763 0.009626 0.022193"
        rpy="0 0 0" />
      <mass
        value="0.53381" />
      <inertia
        ixx="0.00027695"
        ixy="-6.2384E-06"
        ixz="-1.2399E-05"
        iyy="0.0010151"
        iyz="1.3009E-05"
        izz="0.001039" />
    </inertial>
    <visual>
      <origin
        xyz="0 0 0"
        rpy="0 0 0" />
      <geometry>
        <mesh
          filename="package://yori_description/meshes/yori/forearm_left.dae" />
      </geometry>
      <material
        name="">
        <color
          rgba="0.75294 0.75294 0.75294 1" />
      </material>
    </visual>
    <collision>
      <origin
        xyz="0 0 0"
        rpy="0 0 0" />
      <geometry>
        <mesh
          filename="package://yori_description/meshes/yori/forearm_left.dae" />
      </geometry>
    </collision>
  </link>

  <joint
    name="forearm_left_joint"
    type="revolute">
    <origin
      xyz="0 0.4 0"
      rpy="0 0 0" />
    <parent
      link="upperarm_left" />
    <child
      link="forearm_left" />
    <axis
      xyz="0 0 1" />
    <limit
      lower="-0.9599"
      upper="3.14159"
      effort="30"
      velocity="10" />
    <dynamics
      damping="21.75"
      friction="3.48" />
  </joint>

  <link
    name="wrist_left">
    <inertial>
      <origin
        xyz="0.0033388 -4.703E-06 0.0073816"
        rpy="0 0 0" />
      <mass
        value="0.17204" />
      <inertia
        ixx="0.0001158"
        ixy="2.5125E-09"
        ixz="-4.3136E-06"
        iyy="7.675E-05"
        iyz="7.2178E-11"
        izz="7.2857E-05" />
    </inertial>
    <visual>
      <origin
        xyz="0 0 0"
        rpy="0 0 0" />
      <geometry>
        <mesh
          filename="package://yori_description/meshes/yori/wrist_left.dae" />
      </geometry>
      <material
        name="">
        <color
          rgba="0.75294 0.75294 0.75294 1" />
      </material>
    </visual>
    <collision>
      <origin
        xyz="0 0 0"
        rpy="0 0 0" />
      <geometry>
        <mesh
          filename="package://yori_description/meshes/yori/wrist_left.dae" />
      </geometry>
    </collision>
  </link>

  <joint
    name="wrist_left_joint"
    type="revolute">
    <origin
      xyz="0.375 0 0"
      rpy="0 0 0" />
    <parent
      link="forearm_left" />
    <child
      link="wrist_left" />
    <axis
      xyz="0 0 1" />
    <limit
      lower="-2.4435"
      upper="2.4435"
      effort="20"
      velocity="10" />
    <dynamics
      damping="21.75"
      friction="3.48" />
  </joint>

  <link
    name="toolchanger_left">
    <inertial>
      <origin
        xyz="0.0028291 0.0014982 0.054981"
        rpy="0 0 0" />
      <mass
        value="0.10635" />
      <inertia
        ixx="1.7441E-05"
        ixy="4.5012E-11"
        ixz="-2.3526E-06"
        iyy="1.5125E-05"
        iyz="-4.0699E-08"
        izz="2.101E-05" />
    </inertial>
    <visual>
      <origin
        xyz="0 0 0"
        rpy="0 0 0" />
      <geometry>
        <mesh
          filename="package://yori_description/meshes/yori/toolchanger_left.dae" />
      </geometry>
      <material
        name="">
        <color
          rgba="0.75294 0.75294 0.75294 1" />
      </material>
    </visual>
    <collision>
      <origin
        xyz="0 0 0"
        rpy="0 0 0" />
      <geometry>
        <mesh
          filename="package://yori_description/meshes/yori/toolchanger_left.dae" />
      </geometry>
    </collision>
  </link>

  <joint
    name="toolchanger_left_joint"
    type="revolute">
    <origin
      xyz="0.01925 0 0"
      rpy="1.5708 0 1.5708" />
    <parent
      link="wrist_left" />
    <child
      link="toolchanger_left" />
    <axis
      xyz="0 0 1" />
    <limit
      lower="-3.14159"
      upper="3.14159"
      effort="20"
      velocity="10" />
    <dynamics
      damping="21.75"
      friction="3.48" />
  </joint>

  <link
    name="shoulder_right">
    <inertial>
      <origin
        xyz="1.5919E-06 -0.049429 0.00095652"
        rpy="0 0 0" />
      <mass
        value="1.1411" />
      <inertia
        ixx="0.0015526"
        ixy="-1.1487E-08"
        ixz="-8.2652E-09"
        iyy="0.0024227"
        iyz="7.1818E-05"
        izz="0.0029867" />
    </inertial>
    <visual>
      <origin
        xyz="0 0 0"
        rpy="0 0 0" />
      <geometry>
        <mesh
          filename="package://yori_description/meshes/yori/shoulder_right.dae" />
      </geometry>
      <material
        name="">
        <color
          rgba="0.75294 0.75294 0.75294 1" />
      </material>
    </visual>
    <collision>
      <origin
        xyz="0 0 0"
        rpy="0 0 0" />
      <geometry>
        <mesh
          filename="package://yori_description/meshes/yori/shoulder_right.dae" />
      </geometry>
    </collision>
  </link>

  <joint
    name="shoulder_right_joint"
    type="revolute">
    <origin
      xyz="0 -0.21 0.117"
      rpy="0 0 0" />
    <parent
      link="clavicle" />
    <child
      link="shoulder_right" />
    <axis
      xyz="0 0 1" />
    <limit
      lower="-2.2689"
      upper="2.2689"
      effort="30"
      velocity="10" />
    <dynamics
      damping="21.75"
      friction="3.48" />
  </joint>

  <link
    name="upperarm_right">
    <inertial>
      <origin
        xyz="-0.0060639 0.08402 0.001052"
        rpy="0 0 0" />
      <mass
        value="0.77878" />
      <inertia
        ixx="0.0013093"
        ixy="2.2239E-05"
        ixz="2.5263E-06"
        iyy="0.00072415"
        iyz="-1.4488E-05"
        izz="0.0018707" />
    </inertial>
    <visual>
      <origin
        xyz="0 0 0"
        rpy="0 0 0" />
      <geometry>
        <mesh
          filename="package://yori_description/meshes/yori/upperarm_right.dae" />
      </geometry>
      <material
        name="">
        <color
          rgba="0.75294 0.75294 0.75294 1" />
      </material>
    </visual>
    <collision>
      <origin
        xyz="0 0 0"
        rpy="0 0 0" />
      <geometry>
        <mesh
          filename="package://yori_description/meshes/yori/upperarm_right.dae" />
      </geometry>
    </collision>
  </link>

  <joint
    name="upperarm_right_joint"
    type="revolute">
    <origin
      xyz="0 -0.15 0"
      rpy="-1.5708 0 0" />
    <parent
      link="shoulder_right" />
    <child
      link="upperarm_right" />
    <axis
      xyz="0 0 1" />
    <limit
      lower="-3.14159"
      upper="3.14159"
      effort="30"
      velocity="10" />
    <dynamics
      damping="21.75"
      friction="3.48" />
  </joint>

  <link
    name="forearm_right">
    <inertial>
      <origin
        xyz="0.19763 0.0096229 -0.022195"
        rpy="0 0 0" />
      <mass
        value="0.53382" />
      <inertia
        ixx="0.00027696"
        ixy="-6.2394E-06"
        ixz="1.2376E-05"
        iyy="0.0010151"
        iyz="-1.3017E-05"
        izz="0.001039" />
    </inertial>
    <visual>
      <origin
        xyz="0 0 0"
        rpy="0 0 0" />
      <geometry>
        <mesh
          filename="package://yori_description/meshes/yori/forearm_right.dae" />
      </geometry>
      <material
        name="">
        <color
          rgba="0.75294 0.75294 0.75294 1" />
      </material>
    </visual>
    <collision>
      <origin
        xyz="0 0 0"
        rpy="0 0 0" />
      <geometry>
        <mesh
          filename="package://yori_description/meshes/yori/forearm_right.dae" />
      </geometry>
    </collision>
  </link>

  <joint
    name="forearm_right_joint"
    type="revolute">
    <origin
      xyz="0 0.4 0"
      rpy="0 0 0" />
    <parent
      link="upperarm_right" />
    <child
      link="forearm_right" />
    <axis
      xyz="0 0 1" />
    <limit
      lower="-0.9599"
      upper="3.14159"
      effort="30"
      velocity="10" />
    <dynamics
      damping="21.75"
      friction="3.48" />
  </joint>
  
  <link
    name="wrist_right">
    <inertial>
      <origin
        xyz="0.0033388 4.703E-06 -0.0073816"
        rpy="0 0 0" />
      <mass
        value="0.17204" />
      <inertia
        ixx="0.0001158"
        ixy="-2.5125E-09"
        ixz="4.3136E-06"
        iyy="7.675E-05"
        iyz="7.2184E-11"
        izz="7.2857E-05" />
    </inertial>
    <visual>
      <origin
        xyz="0 0 0"
        rpy="0 0 0" />
      <geometry>
        <mesh
          filename="package://yori_description/meshes/yori/wrist_right.dae" />
      </geometry>
      <material
        name="">
        <color
          rgba="0.75294 0.75294 0.75294 1" />
      </material>
    </visual>
    <collision>
      <origin
        xyz="0 0 0"
        rpy="0 0 0" />
      <geometry>
        <mesh
          filename="package://yori_description/meshes/yori/wrist_right.dae" />
      </geometry>
    </collision>
  </link>

  <joint
    name="wrist_right_joint"
    type="revolute">
    <origin
      xyz="0.375 0 0"
      rpy="0 0 0" />
    <parent
      link="forearm_right" />
    <child
      link="wrist_right" />
    <axis
      xyz="0 0 1" />
    <limit
      lower="-2.4435"
      upper="2.4435"
      effort="20"
      velocity="10" />
    <dynamics
      damping="21.75"
      friction="3.48" />
  </joint>

  <link
    name="toolchanger_right">
    <inertial>
      <origin
        xyz="0.0028291 0.0014982 0.054981"
        rpy="0 0 0" />
      <mass
        value="0.10635" />
      <inertia
        ixx="1.7441E-05"
        ixy="4.5012E-11"
        ixz="-2.3526E-06"
        iyy="1.5125E-05"
        iyz="-4.0699E-08"
        izz="2.101E-05" />
    </inertial>
    <visual>
      <origin
        xyz="0 0 0"
        rpy="0 0 0" />
      <geometry>
        <mesh
          filename="package://yori_description/meshes/yori/toolchanger_right.dae" />
      </geometry>
      <material
        name="">
        <color
          rgba="0.75294 0.75294 0.75294 1" />
      </material>
    </visual>
    <collision>
      <origin
        xyz="0 0 0"
        rpy="0 0 0" />
      <geometry>
        <mesh
          filename="package://yori_description/meshes/yori/toolchanger_right.dae" />
      </geometry>
    </collision>
  </link>

  <joint
    name="toolchanger_right_joint"
    type="revolute">
    <origin
      xyz="0.01925 0 0"
      rpy="1.5708 0 1.5708" />
    <parent
      link="wrist_right" />
    <child
      link="toolchanger_right" />
    <axis
      xyz="0 0 1" />
    <limit
      lower="-3.14159"
      upper="3.14159"
      effort="20"
      velocity="10" />
    <dynamics
      damping="21.75"
      friction="3.48" />
  </joint>

</robot>